Workbook

Sheet Gantt
A1: CascoVision · Carta Gantt · Metodología tradicional (cascada)
A2: Inicio del semestre | C2: 46244 | E2: Semana actual | G2: =MAX(1,MIN(18,INT((TODAY()-$C$2)/7)+1))
A4: ID | B4: Fase / Tarea | C4: Responsable | D4: Tipo | E4: Inicio (sem) | F4: Duración (sem) | G4: Fin (sem) | H4: Fecha inicio | I4: Fecha fin | J4: 1 | K4: 2 | L4: 3 | M4: 4 | N4: 5 | O4: 6 | P4: 7 | Q4: 8 | R4: 9 | S4: 10 | T4: 11 | U4: 12 | V4: 13 | W4: 14 | X4: 15 | Y4: 16 | Z4: 17 | AA4: 18
B5: Lunes de cada semana → | J5: =$C$2+(J$4-1)*7 | K5: =$C$2+(K$4-1)*7 | L5: =$C$2+(L$4-1)*7 | M5: =$C$2+(M$4-1)*7 | N5: =$C$2+(N$4-1)*7 | O5: =$C$2+(O$4-1)*7 | P5: =$C$2+(P$4-1)*7 | Q5: =$C$2+(Q$4-1)*7 | ... AA5: =$C$2+(AA$4-1)*7
A6: 1 | B6: Fase 1 · Inicio y planificación | C6: Iahn Vera | D6: Fase | E6: =MIN(E7:E9) | F6: =G6-E6+1 | G6: =MAX(G7:G9) | H6: =IF(E6="","",$C$2+(E6-1)*7) | I6: =IF(G6="","",$C$2+(G6-1)*7+5)
A7: 1.1 | B7: Definición del proyecto y alcance | C7: Equipo | D7: Tarea | E7: 1 | F7: 3 | G7: =E7+F7-1 | H7: =IF(E7="","",$C$2+(E7-1)*7) | I7: =IF(G7="","",$C$2+(G7-1)*7+5)
A8: 1.2 | B8: EDT, cronograma y stack tecnológico | C8: Iahn Vera | D8: Tarea | E8: 2 | F8: 2 | G8: =E8+F8-1 | H8: =IF(E8="","",$C$2+(E8-1)*7) | I8: =IF(G8="","",$C$2+(G8-1)*7+5)
A9: 1.3 | B9: Presentación sumativa Fase 1 | C9: Equipo | D9: Tarea | E9: 4 | F9: 1 | G9: =E9+F9-1 | H9: =IF(E9="","",$C$2+(E9-1)*7) | I9: =IF(G9="","",$C$2+(G9-1)*7+5)
A10: ◆ | B10: Hito · Proyecto definido (Sumativa Fase 1) | C10: Iahn Vera | D10: Hito | E10: 4 | F10: 0 | G10: =E10 | H10: =IF(E10="","",$C$2+(E10-1)*7) | I10: =IF(G10="","",$C$2+(G10-1)*7+5) | J10: =IF(J$4=$E10,"◆","") | K10: =IF(K$4=$E10,"◆","") | L10: =IF(L$4=$E10,"◆","") | M10: =IF(M$4=$E10,"◆","") | N10: =IF(N$4=$E10,"◆","") | O10: =IF(O$4=$E10,"◆","") | P10: =IF(P$4=$E10,"◆","") | Q10: =IF(Q$4=$E10,"◆","") | ... AA10: =IF(AA$4=$E10,"◆","")
A11: 2 | B11: Fase 2 · Análisis de requerimientos | C11: Iahn Vera | D11: Fase | E11: =MIN(E12:E14) | F11: =G11-E11+1 | G11: =MAX(G12:G14) | H11: =IF(E11="","",$C$2+(E11-1)*7) | I11: =IF(G11="","",$C$2+(G11-1)*7+5)
A12: 2.1 | B12: Ajustes por retroalimentación Fase 1 | C12: Iahn Vera | D12: Tarea | E12: 5 | F12: 2 | G12: =E12+F12-1 | H12: =IF(E12="","",$C$2+(E12-1)*7) | I12: =IF(G12="","",$C$2+(G12-1)*7+5)
A13: 2.2 | B13: Especificación de requerimientos (ERS) | C13: Iahn Vera / Joaquín Armijo | D13: Tarea | E13: 6 | F13: 2 | G13: =E13+F13-1 | H13: =IF(E13="","",$C$2+(E13-1)*7) | I13: =IF(G13="","",$C$2+(G13-1)*7+5)
A14: 2.3 | B14: Adquisición de hardware (M5Stack StickS3) | C14: Fernando Muñoz | D14: Tarea | E14: 7 | F14: 1 | G14: =E14+F14-1 | H14: =IF(E14="","",$C$2+(E14-1)*7) | I14: =IF(G14="","",$C$2+(G14-1)*7+5)
A15: ◆ | B15: Hito · ERS aprobada | C15: Iahn Vera | D15: Hito | E15: 7 | F15: 0 | G15: =E15 | H15: =IF(E15="","",$C$2+(E15-1)*7) | I15: =IF(G15="","",$C$2+(G15-1)*7+5) | J15: =IF(J$4=$E15,"◆","") | K15: =IF(K$4=$E15,"◆","") | L15: =IF(L$4=$E15,"◆","") | M15: =IF(M$4=$E15,"◆","") | N15: =IF(N$4=$E15,"◆","") | O15: =IF(O$4=$E15,"◆","") | P15: =IF(P$4=$E15,"◆","") | Q15: =IF(Q$4=$E15,"◆","") | ... AA15: =IF(AA$4=$E15,"◆","")
A16: 3 | B16: Fase 3 · Diseño | C16: Joaquín Armijo | D16: Fase | E16: =MIN(E17:E22) | F16: =G16-E16+1 | G16: =MAX(G17:G22) | H16: =IF(E16="","",$C$2+(E16-1)*7) | I16: =IF(G16="","",$C$2+(G16-1)*7+5)
A17: 3.1 | B17: Arquitectura y diagrama de despliegue | C17: Iahn Vera | D17: Tarea | E17: 8 | F17: 1 | G17: =E17+F17-1 | H17: =IF(E17="","",$C$2+(E17-1)*7) | I17: =IF(G17="","",$C$2+(G17-1)*7+5)
A18: 3.2 | B18: Modelo de datos (diagrama ER) | C18: Joaquín Armijo | D18: Tarea | E18: 8 | F18: 1 | G18: =E18+F18-1 | H18: =IF(E18="","",$C$2+(E18-1)*7) | I18: =IF(G18="","",$C$2+(G18-1)*7+5)
A19: 3.3 | B19: Diseño del protocolo de alerta (/alert, /health) | C19: Fernando Muñoz | D19: Tarea | E19: 8 | F19: 1 | G19: =E19+F19-1 | H19: =IF(E19="","",$C$2+(E19-1)*7) | I19: =IF(G19="","",$C$2+(G19-1)*7+5)
A20: 3.4 | B20: Diseño de interfaz (mockups dashboard) | C20: Benjamín Cáceres | D20: Tarea | E20: 8 | F20: 2 | G20: =E20+F20-1 | H20: =IF(E20="","",$C$2+(E20-1)*7) | I20: =IF(G20="","",$C$2+(G20-1)*7+5)
A21: 3.5 | B21: Plan de pruebas y criterios de aceptación | C21: Fernando Muñoz | D21: Tarea | E21: 9 | F21: 1 | G21: =E21+F21-1 | H21: =IF(E21="","",$C$2+(E21-1)*7) | I21: =IF(G21="","",$C$2+(G21-1)*7+5)
A22: 3.6 | B22: Diseño Docker (contenedores, redes, volúmenes) | C22: Joaquín Armijo | D22: Tarea | E22: 9 | F22: 1 | G22: =E22+F22-1 | H22: =IF(E22="","",$C$2+(E22-1)*7) | I22: =IF(G22="","",$C$2+(G22-1)*7+5)
A23: ◆ | B23: Hito · Documento de diseño aprobado | C23: Joaquín Armijo | D23: Hito | E23: 9 | F23: 0 | G23: =E23 | H23: =IF(E23="","",$C$2+(E23-1)*7) | I23: =IF(G23="","",$C$2+(G23-1)*7+5) | J23: =IF(J$4=$E23,"◆","") | K23: =IF(K$4=$E23,"◆","") | L23: =IF(L$4=$E23,"◆","") | M23: =IF(M$4=$E23,"◆","") | N23: =IF(N$4=$E23,"◆","") | O23: =IF(O$4=$E23,"◆","") | P23: =IF(P$4=$E23,"◆","") | Q23: =IF(Q$4=$E23,"◆","") | ... AA23: =IF(AA$4=$E23,"◆","")
A24: 4 | B24: Fase 4 · Construcción | C24: Joaquín Armijo | D24: Fase | E24: =MIN(E25:E35) | F24: =G24-E24+1 | G24: =MAX(G25:G35) | H24: =IF(E24="","",$C$2+(E24-1)*7) | I24: =IF(G24="","",$C$2+(G24-1)*7+5)
A25: 4.1 | B25: Dataset y entrenamiento YOLOv8 → ONNX | C25: Iahn Vera | D25: Tarea | E25: 9 | F25: 3 | G25: =E25+F25-1 | H25: =IF(E25="","",$C$2+(E25-1)*7) | I25: =IF(G25="","",$C$2+(G25-1)*7+5)
A26: 4.2 | B26: Base de datos PostgreSQL y migraciones | C26: Joaquín Armijo | D26: Tarea | E26: 9 | F26: 2 | G26: =E26+F26-1 | H26: =IF(E26="","",$C$2+(E26-1)*7) | I26: =IF(G26="","",$C$2+(G26-1)*7+5)
A27: 4.3 | B27: API REST (FastAPI) | C27: Joaquín Armijo | D27: Tarea | E27: 10 | F27: 3 | G27: =E27+F27-1 | H27: =IF(E27="","",$C$2+(E27-1)*7) | I27: =IF(G27="","",$C$2+(G27-1)*7+5)
A28: 4.4 | B28: Firmware baliza zonal + receptor simulado | C28: Fernando Muñoz | D28: Tarea | E28: 10 | F28: 3 | G28: =E28+F28-1 | H28: =IF(E28="","",$C$2+(E28-1)*7) | I28: =IF(G28="","",$C$2+(G28-1)*7+5)
A29: 4.5 | B29: Dashboard web (React.js) | C29: Benjamín Cáceres | D29: Tarea | E29: 10 | F29: 4 | G29: =E29+F29-1 | H29: =IF(E29="","",$C$2+(E29-1)*7) | I29: =IF(G29="","",$C$2+(G29-1)*7+5)
A30: 4.6 | B30: Agente Edge (RTSP + inferencia) | C30: Iahn Vera | D30: Tarea | E30: 11 | F30: 2 | G30: =E30+F30-1 | H30: =IF(E30="","",$C$2+(E30-1)*7) | I30: =IF(G30="","",$C$2+(G30-1)*7+5)
A31: 4.7 | B31: Alertas remotas (SMS / correo) | C31: Benjamín Cáceres | D31: Tarea | E31: 12 | F31: 2 | G31: =E31+F31-1 | H31: =IF(E31="","",$C$2+(E31-1)*7) | I31: =IF(G31="","",$C$2+(G31-1)*7+5)
A32: 4.8 | B32: Reportes PDF / Excel | C32: Joaquín Armijo | D32: Tarea | E32: 13 | F32: 1 | G32: =E32+F32-1 | H32: =IF(E32="","",$C$2+(E32-1)*7) | I32: =IF(G32="","",$C$2+(G32-1)*7+5)
A33: 4.9 | B33: Pruebas unitarias por componente | C33: Equipo | D33: Tarea | E33: 10 | F33: 4 | G33: =E33+F33-1 | H33: =IF(E33="","",$C$2+(E33-1)*7) | I33: =IF(G33="","",$C$2+(G33-1)*7+5)
A34: 4.10 | B34: Dockerfiles por servicio (api, dashboard, edge) | C34: Equipo | D34: Tarea | E34: 10 | F34: 3 | G34: =E34+F34-1 | H34: =IF(E34="","",$C$2+(E34-1)*7) | I34: =IF(G34="","",$C$2+(G34-1)*7+5)
A35: 4.11 | B35: docker-compose, .env y simuladores (RTSP, baliza) | C35: Joaquín Armijo | D35: Tarea | E35: 11 | F35: 3 | G35: =E35+F35-1 | H35: =IF(E35="","",$C$2+(E35-1)*7) | I35: =IF(G35="","",$C$2+(G35-1)*7+5)
A36: ◆ | B36: Hito · Entrega de avance (Semana 10) | C36: Joaquín Armijo | D36: Hito | E36: 10 | F36: 0 | G36: =E36 | H36: =IF(E36="","",$C$2+(E36-1)*7) | I36: =IF(G36="","",$C$2+(G36-1)*7+5) | J36: =IF(J$4=$E36,"◆","") | K36: =IF(K$4=$E36,"◆","") | L36: =IF(L$4=$E36,"◆","") | M36: =IF(M$4=$E36,"◆","") | N36: =IF(N$4=$E36,"◆","") | O36: =IF(O$4=$E36,"◆","") | P36: =IF(P$4=$E36,"◆","") | Q36: =IF(Q$4=$E36,"◆","") | ... AA36: =IF(AA$4=$E36,"◆","")
A37: 5 | B37: Fase 5 · Integración y pruebas | C37: Fernando Muñoz | D37: Fase | E37: =MIN(E38:E40) | F37: =G37-E37+1 | G37: =MAX(G38:G40) | H37: =IF(E37="","",$C$2+(E37-1)*7) | I37: =IF(G37="","",$C$2+(G37-1)*7+5)
A38: 5.1 | B38: Integración de componentes | C38: Equipo | D38: Tarea | E38: 13 | F38: 1 | G38: =E38+F38-1 | H38: =IF(E38="","",$C$2+(E38-1)*7) | I38: =IF(G38="","",$C$2+(G38-1)*7+5)
A39: 5.2 | B39: Pruebas de integración y aceptación | C39: Fernando Muñoz | D39: Tarea | E39: 14 | F39: 1 | G39: =E39+F39-1 | H39: =IF(E39="","",$C$2+(E39-1)*7) | I39: =IF(G39="","",$C$2+(G39-1)*7+5)
A40: 5.3 | B40: Corrección de defectos y re-entrenamiento | C40: Equipo | D40: Tarea | E40: 14 | F40: 2 | G40: =E40+F40-1 | H40: =IF(E40="","",$C$2+(E40-1)*7) | I40: =IF(G40="","",$C$2+(G40-1)*7+5)
A41: ◆ | B41: Hito · Informe de pruebas aprobado | C41: Fernando Muñoz | D41: Hito | E41: 14 | F41: 0 | G41: =E41 | H41: =IF(E41="","",$C$2+(E41-1)*7) | I41: =IF(G41="","",$C$2+(G41-1)*7+5) | J41: =IF(J$4=$E41,"◆","") | K41: =IF(K$4=$E41,"◆","") | L41: =IF(L$4=$E41,"◆","") | M41: =IF(M$4=$E41,"◆","") | N41: =IF(N$4=$E41,"◆","") | O41: =IF(O$4=$E41,"◆","") | P41: =IF(P$4=$E41,"◆","") | Q41: =IF(Q$4=$E41,"◆","") | ... AA41: =IF(AA$4=$E41,"◆","")
...

Sheet Hitos del curso
A1: Entregables oficiales de la asignatura PTY4614
A3: Semana | B3: Desde | C3: Hasta | D3: Entregable | E3: Tipo | F3: Evaluación | G3: Fase del modelo que se evidencia
A4: 4 | B4: =Gantt!$C$2+(A4-1)*7 | C4: =Gantt!$C$2+(A4-1)*7+5 | D4: 1.5 Sumativa Fase 1 · Presentación del proyecto | E4: Equipo | F4: Sumativa | G4: 1 · Inicio y planificación
A5: 5 | B5: =Gantt!$C$2+(A5-1)*7 | C5: =Gantt!$C$2+(A5-1)*7+5 | D5: 2.1 Diario de reflexión Fase 2 | E5: Individual | F5: — | G5: 2 · Análisis
A6: 6 | B6: =Gantt!$C$2+(A6-1)*7 | C6: =Gantt!$C$2+(A6-1)*7+5 | D6: Actualización de objetivos, metodología y cronograma · 2.4 Guía Fase 2 | E6: Equipo | F6: — | G6: 2 · Análisis
A7: 8 | B7: =Gantt!$C$2+(A7-1)*7 | C7: =Gantt!$C$2+(A7-1)*7+5 | D7: 2.2 Autoevaluación avance Fase 2 | E7: Individual | F7: — | G7: 3 · Diseño
A8: 9 | B8: =Gantt!$C$2+(A8-1)*7 | C8: =Gantt!$C$2+(A8-1)*7+5 | D8: 2.3 Formativa avance Fase 2 | E8: Equipo | F8: Formativa | G8: 3 · Diseño
A9: 10 | B9: =Gantt!$C$2+(A9-1)*7 | C9: =Gantt!$C$2+(A9-1)*7+5 | D9: Entrega de avance (sin presentación) | E9: Equipo | F9: Sumativa | G9: ERS + diseño + construcción en curso
A10: 11 | B10: =Gantt!$C$2+(A10-1)*7 | C10: =Gantt!$C$2+(A10-1)*7+5 | D10: 2.5 Sumativa avance · 2.6 Guía informe final | E10: Equipo | F10: — | G10: 4 · Construcción
A11: 15 | B11: =Gantt!$C$2+(A11-1)*7 | C11: =Gantt!$C$2+(A11-1)*7+5 | D11: 2.7 Sumativa final Fase 2 · Presentación de desarrollo y resultados | E11: Equipo | F11: Sumativa | G11: 5 y 6 · Pruebas e implantación
A12: 16 | B12: =Gantt!$C$2+(A12-1)*7 | C12: =Gantt!$C$2+(A12-1)*7+5 | D12: 3.1 Diario de reflexión Fase 3 · 3.3 Presentación proyecto APT | E12: Individual / Equipo | F12: — | G12: 7 · Presentación
A13: 17 | B13: =Gantt!$C$2+(A13-1)*7 | C13: =Gantt!$C$2+(A13-1)*7+5 | D13: 3.4 Sumativa Fase 3 · Defensa final (semanas 17 y 18) | E13: Equipo | F13: Sumativa | G13: 7 · Presentación
